2025-07-29 09:49:34,423 - selenium_detailed - INFO - ============================================================
2025-07-29 09:49:34,423 - selenium_detailed - INFO - TEST SESSION STARTED
2025-07-29 09:49:34,424 - selenium_detailed - INFO - ============================================================
2025-07-29 09:49:34,424 - selenium_detailed - INFO - Test Type: selenium
2025-07-29 09:49:34,424 - selenium_detailed - INFO - Timestamp: 20250729_094934
2025-07-29 09:49:34,424 - selenium_detailed - INFO - Session Info: {
  "command": "python manage.py test shop.selenium_tests -v 2",
  "description": "Selenium Tests",
  "test_type": "selenium",
  "working_directory": "C:\\Users\\22i223\\Documents\\Software-Testing-Lab\\e-comm\\ecomm"
}
2025-07-29 09:49:47,690 - selenium_detailed - INFO - Performance - Command Duration: 13.266094207763672 seconds
2025-07-29 09:49:47,690 - selenium_detailed - INFO - STDOUT:
2025-07-29 09:49:47,690 - selenium_detailed - INFO - Found 9 test(s).
Operations to perform:
  Synchronize unmigrated apps: messages, staticfiles
  Apply all migrations: admin, auth, contenttypes, sessions, shop
Synchronizing apps without migrations:
  Creating tables...
    Running deferred SQL...
Running migrations:
  Applying contenttypes.0001_initial... OK
  Applying contenttypes.0002_remove_content_type_name... OK
  Applying auth.0001_initial... OK
  Applying auth.0002_alter_permission_name_max_length... OK
  Applying auth.0003_alter_user_email_max_length... OK
  Applying auth.0004_alter_user_username_opts... OK
  Applying auth.0005_alter_user_last_login_null... OK
  Applying auth.0006_require_contenttypes_0002... OK
  Applying auth.0007_alter_validators_add_error_messages... OK
  Applying auth.0008_alter_user_username_max_length... OK
  Applying auth.0009_alter_user_last_name_max_length... OK
  Applying auth.0010_alter_group_name_max_length... OK
  Applying auth.0011_update_proxy_permissions... OK
  Applying auth.0012_alter_user_first_name_max_length... OK
  Applying shop.0001_initial... OK
  Applying admin.0001_initial... OK
  Applying admin.0002_logentry_remove_auto_add... OK
  Applying admin.0003_logentry_add_action_flag_choices... OK
  Applying sessions.0001_initial... OK
System check identified no issues (0 silenced).

2025-07-29 09:49:47,690 - selenium_detailed - ERROR - STDERR:
2025-07-29 09:49:47,690 - selenium_detailed - ERROR - Creating test database for alias 'default' ('file:memorydb_default?mode=memory&cache=shared')...

test_page_object_model (shop.selenium_tests.PageObjectModelDemo.test_page_object_model)
Demonstrate Page Object Model pattern ... ERROR
test_selenium_rc_vs_webdriver (shop.selenium_tests.SeleniumRCDemo.test_selenium_rc_vs_webdriver)
Demonstrate differences between Selenium RC and WebDriver ... [29/Jul/2025 09:49:39,094] - Broken pipe from ('127.0.0.1', 54762)
[29/Jul/2025 09:49:39,094] - Broken pipe from ('127.0.0.1', 54761)
ok
test_add_to_cart_selenium (shop.selenium_tests.SeleniumWebDriverTest.test_add_to_cart_selenium)
Test adding product to cart using Selenium WebDriver ... ERROR
test_checkout_process_selenium (shop.selenium_tests.SeleniumWebDriverTest.test_checkout_process_selenium)
Test checkout process using Selenium WebDriver ... ERROR
test_dynamic_elements_selenium (shop.selenium_tests.SeleniumWebDriverTest.test_dynamic_elements_selenium)
Test handling of dynamic elements using Selenium WebDriver ... ERROR
test_error_handling_selenium (shop.selenium_tests.SeleniumWebDriverTest.test_error_handling_selenium)
Test error handling using Selenium WebDriver ... ERROR
test_product_browsing_selenium (shop.selenium_tests.SeleniumWebDriverTest.test_product_browsing_selenium)
Test product browsing using Selenium WebDriver ... ERROR
test_user_login_selenium (shop.selenium_tests.SeleniumWebDriverTest.test_user_login_selenium)
Test user login using Selenium WebDriver ... ERROR
test_user_registration_selenium (shop.selenium_tests.SeleniumWebDriverTest.test_user_registration_selenium)
Test user registration using Selenium WebDriver ... ERROR

======================================================================
ERROR: test_page_object_model (shop.selenium_tests.PageObjectModelDemo.test_page_object_model)
Demonstrate Page Object Model pattern
----------------------------------------------------------------------
Traceback (most recent call last):
  File "C:\Users\22i223\Documents\Software-Testing-Lab\e-comm\ecomm\venv\Lib\site-packages\django\db\backends\utils.py", line 105, in _execute
    return self.cursor.execute(sql, params)
           ~~~~~~~~~~~~~~~~~~~^^^^^^^^^^^^^
  File "C:\Users\22i223\Documents\Software-Testing-Lab\e-comm\ecomm\venv\Lib\site-packages\django\db\backends\sqlite3\base.py", line 360, in execute
    return super().execute(query, params)
           ~~~~~~~~~~~~~~~^^^^^^^^^^^^^^^
sqlite3.IntegrityError: NOT NULL constraint failed: shop_shop.owner_id

The above exception was the direct cause of the following exception:

Traceback (most recent call last):
  File "C:\Users\22i223\Documents\Software-Testing-Lab\e-comm\ecomm\shop\selenium_tests.py", line 296, in setUp
    self.shop = Shop.objects.create(name='POM Shop')
                ~~~~~~~~~~~~~~~~~~~^^^^^^^^^^^^^^^^^
  File "C:\Users\22i223\Documents\Software-Testing-Lab\e-comm\ecomm\venv\Lib\site-packages\django\db\models\manager.py", line 87, in manager_method
    return getattr(self.get_queryset(), name)(*args, **kwargs)
           ~~~~~~~~~~~~~~~~~~~~~~~~~~~~~~~~~~^^^^^^^^^^^^^^^^^
  File "C:\Users\22i223\Documents\Software-Testing-Lab\e-comm\ecomm\venv\Lib\site-packages\django\db\models\query.py", line 663, in create
    obj.save(force_insert=True, using=self.db)
    ~~~~~~~~^^^^^^^^^^^^^^^^^^^^^^^^^^^^^^^^^^
  File "C:\Users\22i223\Documents\Software-Testing-Lab\e-comm\ecomm\venv\Lib\site-packages\django\db\models\base.py", line 902, in save
    self.save_base(
    ~~~~~~~~~~~~~~^
        using=using,
        ^^^^^^^^^^^^
    ...<2 lines>...
        update_fields=update_fields,
        ^^^^^^^^^^^^^^^^^^^^^^^^^^^^
    )
    ^
  File "C:\Users\22i223\Documents\Software-Testing-Lab\e-comm\ecomm\venv\Lib\site-packages\django\db\models\base.py", line 1008, in save_base
    updated = self._save_table(
        raw,
    ...<4 lines>...
        update_fields,
    )
  File "C:\Users\22i223\Documents\Software-Testing-Lab\e-comm\ecomm\venv\Lib\site-packages\django\db\models\base.py", line 1169, in _save_table
    results = self._do_insert(
        cls._base_manager, using, fields, returning_fields, raw
    )
  File "C:\Users\22i223\Documents\Software-Testing-Lab\e-comm\ecomm\venv\Lib\site-packages\django\db\models\base.py", line 1210, in _do_insert
    return manager._insert(
           ~~~~~~~~~~~~~~~^
        [self],
        ^^^^^^^
    ...<3 lines>...
        raw=raw,
        ^^^^^^^^
    )
    ^
  File "C:\Users\22i223\Documents\Software-Testing-Lab\e-comm\ecomm\venv\Lib\site-packages\django\db\models\manager.py", line 87, in manager_method
    return getattr(self.get_queryset(), name)(*args, **kwargs)
           ~~~~~~~~~~~~~~~~~~~~~~~~~~~~~~~~~~^^^^^^^^^^^^^^^^^
  File "C:\Users\22i223\Documents\Software-Testing-Lab\e-comm\ecomm\venv\Lib\site-packages\django\db\models\query.py", line 1868, in _insert
    return query.get_compiler(using=using).execute_sql(returning_fields)
           ~~~~~~~~~~~~~~~~~~~~~~~~~~~~~~~~~~~~~~~~~~~^^^^^^^^^^^^^^^^^^
  File "C:\Users\22i223\Documents\Software-Testing-Lab\e-comm\ecomm\venv\Lib\site-packages\django\db\models\sql\compiler.py", line 1882, in execute_sql
    cursor.execute(sql, params)
    ~~~~~~~~~~~~~~^^^^^^^^^^^^^
  File "C:\Users\22i223\Documents\Software-Testing-Lab\e-comm\ecomm\venv\Lib\site-packages\django\db\backends\utils.py", line 79, in execute
    return self._execute_with_wrappers(
           ~~~~~~~~~~~~~~~~~~~~~~~~~~~^
        sql, params, many=False, executor=self._execute
        ^^^^^^^^^^^^^^^^^^^^^^^^^^^^^^^^^^^^^^^^^^^^^^^
    )
    ^
  File "C:\Users\22i223\Documents\Software-Testing-Lab\e-comm\ecomm\venv\Lib\site-packages\django\db\backends\utils.py", line 92, in _execute_with_wrappers
    return executor(sql, params, many, context)
  File "C:\Users\22i223\Documents\Software-Testing-Lab\e-comm\ecomm\venv\Lib\site-packages\django\db\backends\utils.py", line 100, in _execute
    with self.db.wrap_database_errors:
         ^^^^^^^^^^^^^^^^^^^^^^^^^^^^
  File "C:\Users\22i223\Documents\Software-Testing-Lab\e-comm\ecomm\venv\Lib\site-packages\django\db\utils.py", line 91, in __exit__
    raise dj_exc_value.with_traceback(traceback) from exc_value
  File "C:\Users\22i223\Documents\Software-Testing-Lab\e-comm\ecomm\venv\Lib\site-packages\django\db\backends\utils.py", line 105, in _execute
    return self.cursor.execute(sql, params)
           ~~~~~~~~~~~~~~~~~~~^^^^^^^^^^^^^
  File "C:\Users\22i223\Documents\Software-Testing-Lab\e-comm\ecomm\venv\Lib\site-packages\django\db\backends\sqlite3\base.py", line 360, in execute
    return super().execute(query, params)
           ~~~~~~~~~~~~~~~^^^^^^^^^^^^^^^
django.db.utils.IntegrityError: NOT NULL constraint failed: shop_shop.owner_id

======================================================================
ERROR: test_add_to_cart_selenium (shop.selenium_tests.SeleniumWebDriverTest.test_add_to_cart_selenium)
Test adding product to cart using Selenium WebDriver
----------------------------------------------------------------------
Traceback (most recent call last):
  File "C:\Users\22i223\Documents\Software-Testing-Lab\e-comm\ecomm\shop\selenium_tests.py", line 56, in setUp
    self.shop = Shop.objects.create(
                ~~~~~~~~~~~~~~~~~~~^
        name='Test Shop',
        ^^^^^^^^^^^^^^^^^
        description='Test shop for Selenium tests'
        ^^^^^^^^^^^^^^^^^^^^^^^^^^^^^^^^^^^^^^^^^^
    )
    ^
  File "C:\Users\22i223\Documents\Software-Testing-Lab\e-comm\ecomm\venv\Lib\site-packages\django\db\models\manager.py", line 87, in manager_method
    return getattr(self.get_queryset(), name)(*args, **kwargs)
           ~~~~~~~~~~~~~~~~~~~~~~~~~~~~~~~~~~^^^^^^^^^^^^^^^^^
  File "C:\Users\22i223\Documents\Software-Testing-Lab\e-comm\ecomm\venv\Lib\site-packages\django\db\models\query.py", line 661, in create
    obj = self.model(**kwargs)
  File "C:\Users\22i223\Documents\Software-Testing-Lab\e-comm\ecomm\venv\Lib\site-packages\django\db\models\base.py", line 569, in __init__
    raise TypeError(
    ...<2 lines>...
    )
TypeError: Shop() got unexpected keyword arguments: 'description'

======================================================================
ERROR: test_checkout_process_selenium (shop.selenium_tests.SeleniumWebDriverTest.test_checkout_process_selenium)
Test checkout process using Selenium WebDriver
----------------------------------------------------------------------
Traceback (most recent call last):
  File "C:\Users\22i223\Documents\Software-Testing-Lab\e-comm\ecomm\shop\selenium_tests.py", line 56, in setUp
    self.shop = Shop.objects.create(
                ~~~~~~~~~~~~~~~~~~~^
        name='Test Shop',
        ^^^^^^^^^^^^^^^^^
        description='Test shop for Selenium tests'
        ^^^^^^^^^^^^^^^^^^^^^^^^^^^^^^^^^^^^^^^^^^
    )
    ^
  File "C:\Users\22i223\Documents\Software-Testing-Lab\e-comm\ecomm\venv\Lib\site-packages\django\db\models\manager.py", line 87, in manager_method
    return getattr(self.get_queryset(), name)(*args, **kwargs)
           ~~~~~~~~~~~~~~~~~~~~~~~~~~~~~~~~~~^^^^^^^^^^^^^^^^^
  File "C:\Users\22i223\Documents\Software-Testing-Lab\e-comm\ecomm\venv\Lib\site-packages\django\db\models\query.py", line 661, in create
    obj = self.model(**kwargs)
  File "C:\Users\22i223\Documents\Software-Testing-Lab\e-comm\ecomm\venv\Lib\site-packages\django\db\models\base.py", line 569, in __init__
    raise TypeError(
    ...<2 lines>...
    )
TypeError: Shop() got unexpected keyword arguments: 'description'

======================================================================
ERROR: test_dynamic_elements_selenium (shop.selenium_tests.SeleniumWebDriverTest.test_dynamic_elements_selenium)
Test handling of dynamic elements using Selenium WebDriver
----------------------------------------------------------------------
Traceback (most recent call last):
  File "C:\Users\22i223\Documents\Software-Testing-Lab\e-comm\ecomm\shop\selenium_tests.py", line 56, in setUp
    self.shop = Shop.objects.create(
                ~~~~~~~~~~~~~~~~~~~^
        name='Test Shop',
        ^^^^^^^^^^^^^^^^^
        description='Test shop for Selenium tests'
        ^^^^^^^^^^^^^^^^^^^^^^^^^^^^^^^^^^^^^^^^^^
    )
    ^
  File "C:\Users\22i223\Documents\Software-Testing-Lab\e-comm\ecomm\venv\Lib\site-packages\django\db\models\manager.py", line 87, in manager_method
    return getattr(self.get_queryset(), name)(*args, **kwargs)
           ~~~~~~~~~~~~~~~~~~~~~~~~~~~~~~~~~~^^^^^^^^^^^^^^^^^
  File "C:\Users\22i223\Documents\Software-Testing-Lab\e-comm\ecomm\venv\Lib\site-packages\django\db\models\query.py", line 661, in create
    obj = self.model(**kwargs)
  File "C:\Users\22i223\Documents\Software-Testing-Lab\e-comm\ecomm\venv\Lib\site-packages\django\db\models\base.py", line 569, in __init__
    raise TypeError(
    ...<2 lines>...
    )
TypeError: Shop() got unexpected keyword arguments: 'description'

======================================================================
ERROR: test_error_handling_selenium (shop.selenium_tests.SeleniumWebDriverTest.test_error_handling_selenium)
Test error handling using Selenium WebDriver
----------------------------------------------------------------------
Traceback (most recent call last):
  File "C:\Users\22i223\Documents\Software-Testing-Lab\e-comm\ecomm\shop\selenium_tests.py", line 56, in setUp
    self.shop = Shop.objects.create(
                ~~~~~~~~~~~~~~~~~~~^
        name='Test Shop',
        ^^^^^^^^^^^^^^^^^
        description='Test shop for Selenium tests'
        ^^^^^^^^^^^^^^^^^^^^^^^^^^^^^^^^^^^^^^^^^^
    )
    ^
  File "C:\Users\22i223\Documents\Software-Testing-Lab\e-comm\ecomm\venv\Lib\site-packages\django\db\models\manager.py", line 87, in manager_method
    return getattr(self.get_queryset(), name)(*args, **kwargs)
           ~~~~~~~~~~~~~~~~~~~~~~~~~~~~~~~~~~^^^^^^^^^^^^^^^^^
  File "C:\Users\22i223\Documents\Software-Testing-Lab\e-comm\ecomm\venv\Lib\site-packages\django\db\models\query.py", line 661, in create
    obj = self.model(**kwargs)
  File "C:\Users\22i223\Documents\Software-Testing-Lab\e-comm\ecomm\venv\Lib\site-packages\django\db\models\base.py", line 569, in __init__
    raise TypeError(
    ...<2 lines>...
    )
TypeError: Shop() got unexpected keyword arguments: 'description'

======================================================================
ERROR: test_product_browsing_selenium (shop.selenium_tests.SeleniumWebDriverTest.test_product_browsing_selenium)
Test product browsing using Selenium WebDriver
----------------------------------------------------------------------
Traceback (most recent call last):
  File "C:\Users\22i223\Documents\Software-Testing-Lab\e-comm\ecomm\shop\selenium_tests.py", line 56, in setUp
    self.shop = Shop.objects.create(
                ~~~~~~~~~~~~~~~~~~~^
        name='Test Shop',
        ^^^^^^^^^^^^^^^^^
        description='Test shop for Selenium tests'
        ^^^^^^^^^^^^^^^^^^^^^^^^^^^^^^^^^^^^^^^^^^
    )
    ^
  File "C:\Users\22i223\Documents\Software-Testing-Lab\e-comm\ecomm\venv\Lib\site-packages\django\db\models\manager.py", line 87, in manager_method
    return getattr(self.get_queryset(), name)(*args, **kwargs)
           ~~~~~~~~~~~~~~~~~~~~~~~~~~~~~~~~~~^^^^^^^^^^^^^^^^^
  File "C:\Users\22i223\Documents\Software-Testing-Lab\e-comm\ecomm\venv\Lib\site-packages\django\db\models\query.py", line 661, in create
    obj = self.model(**kwargs)
  File "C:\Users\22i223\Documents\Software-Testing-Lab\e-comm\ecomm\venv\Lib\site-packages\django\db\models\base.py", line 569, in __init__
    raise TypeError(
    ...<2 lines>...
    )
TypeError: Shop() got unexpected keyword arguments: 'description'

======================================================================
ERROR: test_user_login_selenium (shop.selenium_tests.SeleniumWebDriverTest.test_user_login_selenium)
Test user login using Selenium WebDriver
----------------------------------------------------------------------
Traceback (most recent call last):
  File "C:\Users\22i223\Documents\Software-Testing-Lab\e-comm\ecomm\shop\selenium_tests.py", line 56, in setUp
    self.shop = Shop.objects.create(
                ~~~~~~~~~~~~~~~~~~~^
        name='Test Shop',
        ^^^^^^^^^^^^^^^^^
        description='Test shop for Selenium tests'
        ^^^^^^^^^^^^^^^^^^^^^^^^^^^^^^^^^^^^^^^^^^
    )
    ^
  File "C:\Users\22i223\Documents\Software-Testing-Lab\e-comm\ecomm\venv\Lib\site-packages\django\db\models\manager.py", line 87, in manager_method
    return getattr(self.get_queryset(), name)(*args, **kwargs)
           ~~~~~~~~~~~~~~~~~~~~~~~~~~~~~~~~~~^^^^^^^^^^^^^^^^^
  File "C:\Users\22i223\Documents\Software-Testing-Lab\e-comm\ecomm\venv\Lib\site-packages\django\db\models\query.py", line 661, in create
    obj = self.model(**kwargs)
  File "C:\Users\22i223\Documents\Software-Testing-Lab\e-comm\ecomm\venv\Lib\site-packages\django\db\models\base.py", line 569, in __init__
    raise TypeError(
    ...<2 lines>...
    )
TypeError: Shop() got unexpected keyword arguments: 'description'

======================================================================
ERROR: test_user_registration_selenium (shop.selenium_tests.SeleniumWebDriverTest.test_user_registration_selenium)
Test user registration using Selenium WebDriver
----------------------------------------------------------------------
Traceback (most recent call last):
  File "C:\Users\22i223\Documents\Software-Testing-Lab\e-comm\ecomm\shop\selenium_tests.py", line 56, in setUp
    self.shop = Shop.objects.create(
                ~~~~~~~~~~~~~~~~~~~^
        name='Test Shop',
        ^^^^^^^^^^^^^^^^^
        description='Test shop for Selenium tests'
        ^^^^^^^^^^^^^^^^^^^^^^^^^^^^^^^^^^^^^^^^^^
    )
    ^
  File "C:\Users\22i223\Documents\Software-Testing-Lab\e-comm\ecomm\venv\Lib\site-packages\django\db\models\manager.py", line 87, in manager_method
    return getattr(self.get_queryset(), name)(*args, **kwargs)
           ~~~~~~~~~~~~~~~~~~~~~~~~~~~~~~~~~~^^^^^^^^^^^^^^^^^
  File "C:\Users\22i223\Documents\Software-Testing-Lab\e-comm\ecomm\venv\Lib\site-packages\django\db\models\query.py", line 661, in create
    obj = self.model(**kwargs)
  File "C:\Users\22i223\Documents\Software-Testing-Lab\e-comm\ecomm\venv\Lib\site-packages\django\db\models\base.py", line 569, in __init__
    raise TypeError(
    ...<2 lines>...
    )
TypeError: Shop() got unexpected keyword arguments: 'description'

----------------------------------------------------------------------
Ran 9 tests in 12.531s

FAILED (errors=8)
Destroying test database for alias 'default' ('file:memorydb_default?mode=memory&cache=shared')...


2025-07-29 09:49:47,702 - selenium_detailed - ERROR - Error: Exit code: 1
2025-07-29 09:49:47,702 - selenium_detailed - DEBUG - Test details: {
  "exit_code": 1,
  "stdout_lines": 29,
  "stderr_lines": 291,
  "stderr": "Creating test database for alias 'default' ('file:memorydb_default?mode=memory&cache=shared')...\n\ntest_page_object_model (shop.selenium_tests.PageObjectModelDemo.test_page_object_model)\nDemonstrate Page Object Model pattern ... ERROR\ntest_selenium_rc_vs_webdriver (shop.selenium_tests.SeleniumRCDemo.test_selenium_rc_vs_webdriver)\nDemonstrate differences between Selenium RC and WebDriver ... [29/Jul/2025 09:49:39,094] - Broken pipe from ('127.0.0.1', 54762)\n[29/Jul/2025 09:49:39,094] - Broken pipe from ('127.0.0.1', 54761)\nok\ntest_add_to_cart_selenium (shop.selenium_tests.SeleniumWebDriverTest.test_add_to_cart_selenium)\nTest adding product to cart using Selenium WebDriver ... ERROR\ntest_checkout_process_selenium (shop.selenium_tests.SeleniumWebDriverTest.test_checkout_process_selenium)\nTest checkout process using Selenium WebDriver ... ERROR\ntest_dynamic_elements_selenium (shop.selenium_tests.SeleniumWebDriverTest.test_dynamic_elements_selenium)\nTest handling of dynamic elements using Selenium WebDriver ... ERROR\ntest_error_handling_selenium (shop.selenium_tests.SeleniumWebDriverTest.test_error_handling_selenium)\nTest error handling using Selenium WebDriver ... ERROR\ntest_product_browsing_selenium (shop.selenium_tests.SeleniumWebDriverTest.test_product_browsing_selenium)\nTest product browsing using Selenium WebDriver ... ERROR\ntest_user_login_selenium (shop.selenium_tests.SeleniumWebDriverTest.test_user_login_selenium)\nTest user login using Selenium WebDriver ... ERROR\ntest_user_registration_selenium (shop.selenium_tests.SeleniumWebDriverTest.test_user_registration_selenium)\nTest user registration using Selenium WebDriver ... ERROR\n\n======================================================================\nERROR: test_page_object_model (shop.selenium_tests.PageObjectModelDemo.test_page_object_model)\nDemonstrate Page Object Model pattern\n----------------------------------------------------------------------\nTraceback (most recent call last):\n  File \"C:\\Users\\22i223\\Documents\\Software-Testing-Lab\\e-comm\\ecomm\\venv\\Lib\\site-packages\\django\\db\\backends\\utils.py\", line 105, in _execute\n    return self.cursor.execute(sql, params)\n           ~~~~~~~~~~~~~~~~~~~^^^^^^^^^^^^^\n  File \"C:\\Users\\22i223\\Documents\\Software-Testing-Lab\\e-comm\\ecomm\\venv\\Lib\\site-packages\\django\\db\\backends\\sqlite3\\base.py\", line 360, in execute\n    return super().execute(query, params)\n           ~~~~~~~~~~~~~~~^^^^^^^^^^^^^^^\nsqlite3.IntegrityError: NOT NULL constraint failed: shop_shop.owner_id\n\nThe above exception was the direct cause of the following exception:\n\nTraceback (most recent call last):\n  File \"C:\\Users\\22i223\\Documents\\Software-Testing-Lab\\e-comm\\ecomm\\shop\\selenium_tests.py\", line 296, in setUp\n    self.shop = Shop.objects.create(name='POM Shop')\n                ~~~~~~~~~~~~~~~~~~~^^^^^^^^^^^^^^^^^\n  File \"C:\\Users\\22i223\\Documents\\Software-Testing-Lab\\e-comm\\ecomm\\venv\\Lib\\site-packages\\django\\db\\models\\manager.py\", line 87, in manager_method\n    return getattr(self.get_queryset(), name)(*args, **kwargs)\n           ~~~~~~~~~~~~~~~~~~~~~~~~~~~~~~~~~~^^^^^^^^^^^^^^^^^\n  File \"C:\\Users\\22i223\\Documents\\Software-Testing-Lab\\e-comm\\ecomm\\venv\\Lib\\site-packages\\django\\db\\models\\query.py\", line 663, in create\n    obj.save(force_insert=True, using=self.db)\n    ~~~~~~~~^^^^^^^^^^^^^^^^^^^^^^^^^^^^^^^^^^\n  File \"C:\\Users\\22i223\\Documents\\Software-Testing-Lab\\e-comm\\ecomm\\venv\\Lib\\site-packages\\django\\db\\models\\base.py\", line 902, in save\n    self.save_base(\n    ~~~~~~~~~~~~~~^\n        using=using,\n        ^^^^^^^^^^^^\n    ...<2 lines>...\n        update_fields=update_fields,\n        ^^^^^^^^^^^^^^^^^^^^^^^^^^^^\n    )\n    ^\n  File \"C:\\Users\\22i223\\Documents\\Software-Testing-Lab\\e-comm\\ecomm\\venv\\Lib\\site-packages\\django\\db\\models\\base.py\", line 1008, in save_base\n    updated = self._save_table(\n        raw,\n    ...<4 lines>...\n        update_fields,\n    )\n  File \"C:\\Users\\22i223\\Documents\\Software-Testing-Lab\\e-comm\\ecomm\\venv\\Lib\\site-packages\\django\\db\\models\\base.py\", line 1169, in _save_table\n    results = self._do_insert(\n        cls._base_manager, using, fields, returning_fields, raw\n    )\n  File \"C:\\Users\\22i223\\Documents\\Software-Testing-Lab\\e-comm\\ecomm\\venv\\Lib\\site-packages\\django\\db\\models\\base.py\", line 1210, in _do_insert\n    return manager._insert(\n           ~~~~~~~~~~~~~~~^\n        [self],\n        ^^^^^^^\n    ...<3 lines>...\n        raw=raw,\n        ^^^^^^^^\n    )\n    ^\n  File \"C:\\Users\\22i223\\Documents\\Software-Testing-Lab\\e-comm\\ecomm\\venv\\Lib\\site-packages\\django\\db\\models\\manager.py\", line 87, in manager_method\n    return getattr(self.get_queryset(), name)(*args, **kwargs)\n           ~~~~~~~~~~~~~~~~~~~~~~~~~~~~~~~~~~^^^^^^^^^^^^^^^^^\n  File \"C:\\Users\\22i223\\Documents\\Software-Testing-Lab\\e-comm\\ecomm\\venv\\Lib\\site-packages\\django\\db\\models\\query.py\", line 1868, in _insert\n    return query.get_compiler(using=using).execute_sql(returning_fields)\n           ~~~~~~~~~~~~~~~~~~~~~~~~~~~~~~~~~~~~~~~~~~~^^^^^^^^^^^^^^^^^^\n  File \"C:\\Users\\22i223\\Documents\\Software-Testing-Lab\\e-comm\\ecomm\\venv\\Lib\\site-packages\\django\\db\\models\\sql\\compiler.py\", line 1882, in execute_sql\n    cursor.execute(sql, params)\n    ~~~~~~~~~~~~~~^^^^^^^^^^^^^\n  File \"C:\\Users\\22i223\\Documents\\Software-Testing-Lab\\e-comm\\ecomm\\venv\\Lib\\site-packages\\django\\db\\backends\\utils.py\", line 79, in execute\n    return self._execute_with_wrappers(\n           ~~~~~~~~~~~~~~~~~~~~~~~~~~~^\n        sql, params, many=False, executor=self._execute\n        ^^^^^^^^^^^^^^^^^^^^^^^^^^^^^^^^^^^^^^^^^^^^^^^\n    )\n    ^\n  File \"C:\\Users\\22i223\\Documents\\Software-Testing-Lab\\e-comm\\ecomm\\venv\\Lib\\site-packages\\django\\db\\backends\\utils.py\", line 92, in _execute_with_wrappers\n    return executor(sql, params, many, context)\n  File \"C:\\Users\\22i223\\Documents\\Software-Testing-Lab\\e-comm\\ecomm\\venv\\Lib\\site-packages\\django\\db\\backends\\utils.py\", line 100, in _execute\n    with self.db.wrap_database_errors:\n         ^^^^^^^^^^^^^^^^^^^^^^^^^^^^\n  File \"C:\\Users\\22i223\\Documents\\Software-Testing-Lab\\e-comm\\ecomm\\venv\\Lib\\site-packages\\django\\db\\utils.py\", line 91, in __exit__\n    raise dj_exc_value.with_traceback(traceback) from exc_value\n  File \"C:\\Users\\22i223\\Documents\\Software-Testing-Lab\\e-comm\\ecomm\\venv\\Lib\\site-packages\\django\\db\\backends\\utils.py\", line 105, in _execute\n    return self.cursor.execute(sql, params)\n           ~~~~~~~~~~~~~~~~~~~^^^^^^^^^^^^^\n  File \"C:\\Users\\22i223\\Documents\\Software-Testing-Lab\\e-comm\\ecomm\\venv\\Lib\\site-packages\\django\\db\\backends\\sqlite3\\base.py\", line 360, in execute\n    return super().execute(query, params)\n           ~~~~~~~~~~~~~~~^^^^^^^^^^^^^^^\ndjango.db.utils.IntegrityError: NOT NULL constraint failed: shop_shop.owner_id\n\n======================================================================\nERROR: test_add_to_cart_selenium (shop.selenium_tests.SeleniumWebDriverTest.test_add_to_cart_selenium)\nTest adding product to cart using Selenium WebDriver\n----------------------------------------------------------------------\nTraceback (most recent call last):\n  File \"C:\\Users\\22i223\\Documents\\Software-Testing-Lab\\e-comm\\ecomm\\shop\\selenium_tests.py\", line 56, in setUp\n    self.shop = Shop.objects.create(\n                ~~~~~~~~~~~~~~~~~~~^\n        name='Test Shop',\n        ^^^^^^^^^^^^^^^^^\n        description='Test shop for Selenium tests'\n        ^^^^^^^^^^^^^^^^^^^^^^^^^^^^^^^^^^^^^^^^^^\n    )\n    ^\n  File \"C:\\Users\\22i223\\Documents\\Software-Testing-Lab\\e-comm\\ecomm\\venv\\Lib\\site-packages\\django\\db\\models\\manager.py\", line 87, in manager_method\n    return getattr(self.get_queryset(), name)(*args, **kwargs)\n           ~~~~~~~~~~~~~~~~~~~~~~~~~~~~~~~~~~^^^^^^^^^^^^^^^^^\n  File \"C:\\Users\\22i223\\Documents\\Software-Testing-Lab\\e-comm\\ecomm\\venv\\Lib\\site-packages\\django\\db\\models\\query.py\", line 661, in create\n    obj = self.model(**kwargs)\n  File \"C:\\Users\\22i223\\Documents\\Software-Testing-Lab\\e-comm\\ecomm\\venv\\Lib\\site-packages\\django\\db\\models\\base.py\", line 569, in __init__\n    raise TypeError(\n    ...<2 lines>...\n    )\nTypeError: Shop() got unexpected keyword arguments: 'description'\n\n======================================================================\nERROR: test_checkout_process_selenium (shop.selenium_tests.SeleniumWebDriverTest.test_checkout_process_selenium)\nTest checkout process using Selenium WebDriver\n----------------------------------------------------------------------\nTraceback (most recent call last):\n  File \"C:\\Users\\22i223\\Documents\\Software-Testing-Lab\\e-comm\\ecomm\\shop\\selenium_tests.py\", line 56, in setUp\n    self.shop = Shop.objects.create(\n                ~~~~~~~~~~~~~~~~~~~^\n        name='Test Shop',\n        ^^^^^^^^^^^^^^^^^\n        description='Test shop for Selenium tests'\n        ^^^^^^^^^^^^^^^^^^^^^^^^^^^^^^^^^^^^^^^^^^\n    )\n    ^\n  File \"C:\\Users\\22i223\\Documents\\Software-Testing-Lab\\e-comm\\ecomm\\venv\\Lib\\site-packages\\django\\db\\models\\manager.py\", line 87, in manager_method\n    return getattr(self.get_queryset(), name)(*args, **kwargs)\n           ~~~~~~~~~~~~~~~~~~~~~~~~~~~~~~~~~~^^^^^^^^^^^^^^^^^\n  File \"C:\\Users\\22i223\\Documents\\Software-Testing-Lab\\e-comm\\ecomm\\venv\\Lib\\site-packages\\django\\db\\models\\query.py\", line 661, in create\n    obj = self.model(**kwargs)\n  File \"C:\\Users\\22i223\\Documents\\Software-Testing-Lab\\e-comm\\ecomm\\venv\\Lib\\site-packages\\django\\db\\models\\base.py\", line 569, in __init__\n    raise TypeError(\n    ...<2 lines>...\n    )\nTypeError: Shop() got unexpected keyword arguments: 'description'\n\n======================================================================\nERROR: test_dynamic_elements_selenium (shop.selenium_tests.SeleniumWebDriverTest.test_dynamic_elements_selenium)\nTest handling of dynamic elements using Selenium WebDriver\n----------------------------------------------------------------------\nTraceback (most recent call last):\n  File \"C:\\Users\\22i223\\Documents\\Software-Testing-Lab\\e-comm\\ecomm\\shop\\selenium_tests.py\", line 56, in setUp\n    self.shop = Shop.objects.create(\n                ~~~~~~~~~~~~~~~~~~~^\n        name='Test Shop',\n        ^^^^^^^^^^^^^^^^^\n        description='Test shop for Selenium tests'\n        ^^^^^^^^^^^^^^^^^^^^^^^^^^^^^^^^^^^^^^^^^^\n    )\n    ^\n  File \"C:\\Users\\22i223\\Documents\\Software-Testing-Lab\\e-comm\\ecomm\\venv\\Lib\\site-packages\\django\\db\\models\\manager.py\", line 87, in manager_method\n    return getattr(self.get_queryset(), name)(*args, **kwargs)\n           ~~~~~~~~~~~~~~~~~~~~~~~~~~~~~~~~~~^^^^^^^^^^^^^^^^^\n  File \"C:\\Users\\22i223\\Documents\\Software-Testing-Lab\\e-comm\\ecomm\\venv\\Lib\\site-packages\\django\\db\\models\\query.py\", line 661, in create\n    obj = self.model(**kwargs)\n  File \"C:\\Users\\22i223\\Documents\\Software-Testing-Lab\\e-comm\\ecomm\\venv\\Lib\\site-packages\\django\\db\\models\\base.py\", line 569, in __init__\n    raise TypeError(\n    ...<2 lines>...\n    )\nTypeError: Shop() got unexpected keyword arguments: 'description'\n\n======================================================================\nERROR: test_error_handling_selenium (shop.selenium_tests.SeleniumWebDriverTest.test_error_handling_selenium)\nTest error handling using Selenium WebDriver\n----------------------------------------------------------------------\nTraceback (most recent call last):\n  File \"C:\\Users\\22i223\\Documents\\Software-Testing-Lab\\e-comm\\ecomm\\shop\\selenium_tests.py\", line 56, in setUp\n    self.shop = Shop.objects.create(\n                ~~~~~~~~~~~~~~~~~~~^\n        name='Test Shop',\n        ^^^^^^^^^^^^^^^^^\n        description='Test shop for Selenium tests'\n        ^^^^^^^^^^^^^^^^^^^^^^^^^^^^^^^^^^^^^^^^^^\n    )\n    ^\n  File \"C:\\Users\\22i223\\Documents\\Software-Testing-Lab\\e-comm\\ecomm\\venv\\Lib\\site-packages\\django\\db\\models\\manager.py\", line 87, in manager_method\n    return getattr(self.get_queryset(), name)(*args, **kwargs)\n           ~~~~~~~~~~~~~~~~~~~~~~~~~~~~~~~~~~^^^^^^^^^^^^^^^^^\n  File \"C:\\Users\\22i223\\Documents\\Software-Testing-Lab\\e-comm\\ecomm\\venv\\Lib\\site-packages\\django\\db\\models\\query.py\", line 661, in create\n    obj = self.model(**kwargs)\n  File \"C:\\Users\\22i223\\Documents\\Software-Testing-Lab\\e-comm\\ecomm\\venv\\Lib\\site-packages\\django\\db\\models\\base.py\", line 569, in __init__\n    raise TypeError(\n    ...<2 lines>...\n    )\nTypeError: Shop() got unexpected keyword arguments: 'description'\n\n======================================================================\nERROR: test_product_browsing_selenium (shop.selenium_tests.SeleniumWebDriverTest.test_product_browsing_selenium)\nTest product browsing using Selenium WebDriver\n----------------------------------------------------------------------\nTraceback (most recent call last):\n  File \"C:\\Users\\22i223\\Documents\\Software-Testing-Lab\\e-comm\\ecomm\\shop\\selenium_tests.py\", line 56, in setUp\n    self.shop = Shop.objects.create(\n                ~~~~~~~~~~~~~~~~~~~^\n        name='Test Shop',\n        ^^^^^^^^^^^^^^^^^\n        description='Test shop for Selenium tests'\n        ^^^^^^^^^^^^^^^^^^^^^^^^^^^^^^^^^^^^^^^^^^\n    )\n    ^\n  File \"C:\\Users\\22i223\\Documents\\Software-Testing-Lab\\e-comm\\ecomm\\venv\\Lib\\site-packages\\django\\db\\models\\manager.py\", line 87, in manager_method\n    return getattr(self.get_queryset(), name)(*args, **kwargs)\n           ~~~~~~~~~~~~~~~~~~~~~~~~~~~~~~~~~~^^^^^^^^^^^^^^^^^\n  File \"C:\\Users\\22i223\\Documents\\Software-Testing-Lab\\e-comm\\ecomm\\venv\\Lib\\site-packages\\django\\db\\models\\query.py\", line 661, in create\n    obj = self.model(**kwargs)\n  File \"C:\\Users\\22i223\\Documents\\Software-Testing-Lab\\e-comm\\ecomm\\venv\\Lib\\site-packages\\django\\db\\models\\base.py\", line 569, in __init__\n    raise TypeError(\n    ...<2 lines>...\n    )\nTypeError: Shop() got unexpected keyword arguments: 'description'\n\n======================================================================\nERROR: test_user_login_selenium (shop.selenium_tests.SeleniumWebDriverTest.test_user_login_selenium)\nTest user login using Selenium WebDriver\n----------------------------------------------------------------------\nTraceback (most recent call last):\n  File \"C:\\Users\\22i223\\Documents\\Software-Testing-Lab\\e-comm\\ecomm\\shop\\selenium_tests.py\", line 56, in setUp\n    self.shop = Shop.objects.create(\n                ~~~~~~~~~~~~~~~~~~~^\n        name='Test Shop',\n        ^^^^^^^^^^^^^^^^^\n        description='Test shop for Selenium tests'\n        ^^^^^^^^^^^^^^^^^^^^^^^^^^^^^^^^^^^^^^^^^^\n    )\n    ^\n  File \"C:\\Users\\22i223\\Documents\\Software-Testing-Lab\\e-comm\\ecomm\\venv\\Lib\\site-packages\\django\\db\\models\\manager.py\", line 87, in manager_method\n    return getattr(self.get_queryset(), name)(*args, **kwargs)\n           ~~~~~~~~~~~~~~~~~~~~~~~~~~~~~~~~~~^^^^^^^^^^^^^^^^^\n  File \"C:\\Users\\22i223\\Documents\\Software-Testing-Lab\\e-comm\\ecomm\\venv\\Lib\\site-packages\\django\\db\\models\\query.py\", line 661, in create\n    obj = self.model(**kwargs)\n  File \"C:\\Users\\22i223\\Documents\\Software-Testing-Lab\\e-comm\\ecomm\\venv\\Lib\\site-packages\\django\\db\\models\\base.py\", line 569, in __init__\n    raise TypeError(\n    ...<2 lines>...\n    )\nTypeError: Shop() got unexpected keyword arguments: 'description'\n\n======================================================================\nERROR: test_user_registration_selenium (shop.selenium_tests.SeleniumWebDriverTest.test_user_registration_selenium)\nTest user registration using Selenium WebDriver\n----------------------------------------------------------------------\nTraceback (most recent call last):\n  File \"C:\\Users\\22i223\\Documents\\Software-Testing-Lab\\e-comm\\ecomm\\shop\\selenium_tests.py\", line 56, in setUp\n    self.shop = Shop.objects.create(\n                ~~~~~~~~~~~~~~~~~~~^\n        name='Test Shop',\n        ^^^^^^^^^^^^^^^^^\n        description='Test shop for Selenium tests'\n        ^^^^^^^^^^^^^^^^^^^^^^^^^^^^^^^^^^^^^^^^^^\n    )\n    ^\n  File \"C:\\Users\\22i223\\Documents\\Software-Testing-Lab\\e-comm\\ecomm\\venv\\Lib\\site-packages\\django\\db\\models\\manager.py\", line 87, in manager_method\n    return getattr(self.get_queryset(), name)(*args, **kwargs)\n           ~~~~~~~~~~~~~~~~~~~~~~~~~~~~~~~~~~^^^^^^^^^^^^^^^^^\n  File \"C:\\Users\\22i223\\Documents\\Software-Testing-Lab\\e-comm\\ecomm\\venv\\Lib\\site-packages\\django\\db\\models\\query.py\", line 661, in create\n    obj = self.model(**kwargs)\n  File \"C:\\Users\\22i223\\Documents\\Software-Testing-Lab\\e-comm\\ecomm\\venv\\Lib\\site-packages\\django\\db\\models\\base.py\", line 569, in __init__\n    raise TypeError(\n    ...<2 lines>...\n    )\nTypeError: Shop() got unexpected keyword arguments: 'description'\n\n----------------------------------------------------------------------\nRan 9 tests in 12.531s\n\nFAILED (errors=8)\nDestroying test database for alias 'default' ('file:memorydb_default?mode=memory&cache=shared')...\n\n"
}
2025-07-29 09:49:47,706 - selenium_detailed - ERROR - Error: float division by zero
2025-07-29 09:49:47,706 - selenium_detailed - DEBUG - Test details: {
  "exception_type": "ZeroDivisionError",
  "exception_message": "float division by zero"
}
